Workbook
Name Inflation: Inputs!$B$23

Sheet NPV
C2: INPUTS
C3: Transaction Costs | G3: Financing Inputs
C4: Realtor fees | D4: 0.06 | E4: Selling | G4: Hurdle rate | H4: 0.1
C5: Closing costs (buyer) | D5: 0.02 | E5: Buying | G5: Sale price | H5: =F13 -> 780000
C6: Loan origination fees | D6: 0.015 | E6: Buying | G6: Mortgage at Sale | H6: =G13 -> 600860.19
C7: Inspections/appraisals | D7: 2500 | E7: Buying | G7: Selling costs | H7: =H5*(0.06)+F30*(D5+D6)+D7+D8 -> #N/A
C8: Capital repairs post-close | D8: 5000 | E8: Buying | G8: Net Equity Post Sale | H8: =H5-H6-H7 -> #N/A
C9: Home appreciation | D9: 0.025 | E9: Both | K9: Hold
K10: NPV | L10: IRR
C11: HOLD DUPLEX | D11: FP4 | J11: CoC | K11: =SUM(K13:K24) -> 242531.21 | L11: =IRR(L12:L24) -> 0.17774713
D12: Yr | E12: CF | F12: Prop Value | G12: Loan | H12: Equity | L12: =-H13 -> -179139.81
D13: 2025 | E13: 2764.3471 | F13: 780000 | G13: =_xlfn.XLOOKUP(D13,'FP3 Amort'!$A$3:$A$389,'FP3 Amort'!$G$3:$G$389,,0,-1) -> 600860.19 | H13: =F13-G13 -> 179139.81 | K13: =(E13)/(1+$H$4)^(D13-2025) -> 2764.3471 | L13: =E13 -> 2764.3471
D14: =D13+1 -> 2026 | E14: 3148.1678 | F14: =F13*(1+$D$9) -> 799500 | G14: =_xlfn.XLOOKUP(D14,'FP3 Amort'!$A$3:$A$389,'FP3 Amort'!$G$3:$G$389,,0,-1) -> 587097.21 | H14: =F14-G14 -> 212402.79 | K14: =(E14)/(1+$H$4)^(D14-2025) -> 2861.9707 | L14: =E14 -> 3148.1678
D15: =D14+1 -> 2027 | E15: 4534.206 | F15: =F14*(1+$D$9) -> 819487.5 | G15: =_xlfn.XLOOKUP(D15,'FP3 Amort'!$A$3:$A$389,'FP3 Amort'!$G$3:$G$389,,0,-1) -> 572817.7 | H15: =F15-G15 -> 246669.8 | K15: =(E15)/(1+$H$4)^(D15-2025) -> 3747.2777 | L15: =E15 -> 4534.206
D16: =D15+1 -> 2028 | E16: 5962.2555 | F16: =F15*(1+$D$9) -> 839974.69 | G16: =_xlfn.XLOOKUP(D16,'FP3 Amort'!$A$3:$A$389,'FP3 Amort'!$G$3:$G$389,,0,-1) -> 558002.27 | H16: =F16-G16 -> 281972.42 | K16: =(E16)/(1+$H$4)^(D16-2025) -> 4479.5308 | L16: =E16 -> 5962.2555
D17: =D16+1 -> 2029 | E17: 7433.5875 | F17: =F16*(1+$D$9) -> 860974.05 | G17: =_xlfn.XLOOKUP(D17,'FP3 Amort'!$A$3:$A$389,'FP3 Amort'!$G$3:$G$389,,0,-1) -> 542630.81 | H17: =F17-G17 -> 318343.25 | K17: =(E17)/(1+$H$4)^(D17-2025) -> 5077.2403 | L17: =E17 -> 7433.5875
D18: =D17+1 -> 2030 | E18: 8949.5113 | F18: =F17*(1+$D$9) -> 882498.41 | G18: =_xlfn.XLOOKUP(D18,'FP3 Amort'!$A$3:$A$389,'FP3 Amort'!$G$3:$G$389,,0,-1) -> 526682.44 | H18: =F18-G18 -> 355815.96 | K18: =(E18)/(1+$H$4)^(D18-2025) -> 5556.9424 | L18: =E18 -> 8949.5113
D19: =D18+1 -> 2031 | E19: 10511.376 | F19: =F18*(1+$D$9) -> 904560.87 | G19: =_xlfn.XLOOKUP(D19,'FP3 Amort'!$A$3:$A$389,'FP3 Amort'!$G$3:$G$389,,0,-1) -> 510135.53 | H19: =F19-G19 -> 394425.33 | K19: =(E19)/(1+$H$4)^(D19-2025) -> 5933.3978 | L19: =E19 -> 10511.376
D20: =D19+1 -> 2032 | E20: 12120.572 | F20: =F19*(1+$D$9) -> 927174.89 | G20: =_xlfn.XLOOKUP(D20,'FP3 Amort'!$A$3:$A$389,'FP3 Amort'!$G$3:$G$389,,0,-1) -> 492967.61 | H20: =F20-G20 -> 434207.28 | K20: =(E20)/(1+$H$4)^(D20-2025) -> 6219.7699 | L20: =E20 -> 12120.572
D21: =D20+1 -> 2033 | E21: 13778.53 | F21: =F20*(1+$D$9) -> 950354.26 | G21: =_xlfn.XLOOKUP(D21,'FP3 Amort'!$A$3:$A$389,'FP3 Amort'!$G$3:$G$389,,0,-1) -> 475155.36 | H21: =F21-G21 -> 475198.9 | K21: =(E21)/(1+$H$4)^(D21-2025) -> 6427.786 | L21: =E21 -> 13778.53
D22: =D21+1 -> 2034 | E22: 15486.726 | F22: =F21*(1+$D$9) -> 974113.12 | G22: =_xlfn.XLOOKUP(D22,'FP3 Amort'!$A$3:$A$389,'FP3 Amort'!$G$3:$G$389,,0,-1) -> 456674.61 | H22: =F22-G22 -> 517438.5 | K22: =(E22)/(1+$H$4)^(D22-2025) -> 6567.8836 | L22: =E22 -> 15486.726
D23: =D22+1 -> 2035 | E23: 17246.679 | F23: =F22*(1+$D$9) -> 998465.94 | G23: =_xlfn.XLOOKUP(D23,'FP3 Amort'!$A$3:$A$389,'FP3 Amort'!$G$3:$G$389,,0,-1) -> 437500.27 | H23: =F23-G23 -> 560965.67 | K23: =(E23)/(1+$H$4)^(D23-2025) -> 6649.3414 | L23: =E23 -> 17246.679
D24: =D23+1 -> 2036 | E24: 19059.955 | F24: =F23*(1+$D$9) -> 1023427.6 | G24: =_xlfn.XLOOKUP(D24,'FP3 Amort'!$A$3:$A$389,'FP3 Amort'!$G$3:$G$389,,0,-1) -> 417606.31 | H24: =F24-G24 -> 605821.28 | K24: =(E24)/(1+$H$4)^(D24-2025)+(F24)/(1+$H$4)^(D24-2025)-$H$13 -> 186245.72 | L24: =E24+F24 -> 1042487.5
D27: 1031 | K27: NPV | L27: IRR
D28: Yr | E28: CF | F28: Prop Value | G28: Loan | H28: Equity | K28: =SUM(K30:K41) -> #N/A | L28: =IRR(L29:L42) -> #VALUE!
L29: =-H8 -> #N/A
D30: 2025 | E30: =Financials!N80 -> #N/A | F30: =Inputs!B11 -> #N/A | G30: =_xlfn.XLOOKUP(D30,Amort!$A$3:$A$485,Amort!$C$3:$C$485) -> #N/A | H30: =F30-G30 -> #N/A | K30: =(E30)/(1+$H$4)^(D30-2025) -> #N/A | L30: =E30 -> #N/A
D31: =D30+1 -> 2026 | E31: =Financials!AA80 -> #N/A | F31: =F30*(1+$D$9) -> #N/A | G31: =_xlfn.XLOOKUP(D31,Amort!$A$3:$A$485,Amort!$C$3:$C$485) -> #N/A | H31: =F31-G31 -> #N/A | K31: =(E31)/(1+$H$4)^(D31-2025) -> #N/A | L31: =E31 -> #N/A
D32: =D31+1 -> 2027 | E32: =Financials!AN80 -> #N/A | F32: =F31*(1+$D$9) -> #N/A | G32: =_xlfn.XLOOKUP(D32,Amort!$A$3:$A$485,Amort!$C$3:$C$485) -> #N/A | H32: =F32-G32 -> #N/A | K32: =(E32)/(1+$H$4)^(D32-2025) -> #N/A | L32: =E32 -> #N/A
D33: =D32+1 -> 2028 | E33: =Financials!BA80 -> #N/A | F33: =F32*(1+$D$9) -> #N/A | G33: =_xlfn.XLOOKUP(D33,Amort!$A$3:$A$485,Amort!$C$3:$C$485) -> #N/A | H33: =F33-G33 -> #N/A | K33: =(E33)/(1+$H$4)^(D33-2025) -> #N/A | L33: =E33 -> #N/A
D34: =D33+1 -> 2029 | E34: =Financials!BN80 -> #N/A | F34: =F33*(1+$D$9) -> #N/A | G34: =_xlfn.XLOOKUP(D34,Amort!$A$3:$A$485,Amort!$C$3:$C$485) -> #N/A | H34: =F34-G34 -> #N/A | K34: =(E34)/(1+$H$4)^(D34-2025) -> #N/A | L34: =E34 -> #N/A
D35: =D34+1 -> 2030 | E35: =Financials!CA80 -> #N/A | F35: =F34*(1+$D$9) -> #N/A | G35: =_xlfn.XLOOKUP(D35,Amort!$A$3:$A$485,Amort!$C$3:$C$485) -> #N/A | H35: =F35-G35 -> #N/A | K35: =(E35)/(1+$H$4)^(D35-2025) -> #N/A | L35: =E35 -> #N/A
D36: =D35+1 -> 2031 | E36: =Financials!CN80 -> #N/A | F36: =F35*(1+$D$9) -> #N/A | G36: =_xlfn.XLOOKUP(D36,Amort!$A$3:$A$485,Amort!$C$3:$C$485) -> #N/A | H36: =F36-G36 -> #N/A | K36: =(E36)/(1+$H$4)^(D36-2025) -> #N/A | L36: =E36 -> #N/A
D37: =D36+1 -> 2032 | E37: =Financials!DA80 -> #N/A | F37: =F36*(1+$D$9) -> #N/A | G37: =_xlfn.XLOOKUP(D37,Amort!$A$3:$A$485,Amort!$C$3:$C$485) -> #N/A | H37: =F37-G37 -> #N/A | K37: =(E37)/(1+$H$4)^(D37-2025) -> #N/A | L37: =E37 -> #N/A
D38: =D37+1 -> 2033 | E38: =Financials!DN80 -> #N/A | F38: =F37*(1+$D$9) -> #N/A | G38: =_xlfn.XLOOKUP(D38,Amort!$A$3:$A$485,Amort!$C$3:$C$485) -> #N/A | H38: =F38-G38 -> #N/A | K38: =(E38)/(1+$H$4)^(D38-2025) -> #N/A | L38: =E38 -> #N/A
D39: =D38+1 -> 2034 | E39: =Financials!EA80 -> #N/A | F39: =F38*(1+$D$9) -> #N/A | G39: =_xlfn.XLOOKUP(D39,Amort!$A$3:$A$485,Amort!$C$3:$C$485) -> #N/A | H39: =F39-G39 -> #N/A | K39: =(E39)/(1+$H$4)^(D39-2025) -> #N/A | L39: =E39 -> #N/A
D40: =D39+1 -> 2035 | E40: =Financials!EN80 -> #N/A | F40: =F39*(1+$D$9) -> #N/A | G40: =_xlfn.XLOOKUP(D40,Amort!$A$3:$A$485,Amort!$C$3:$C$485) -> #N/A | H40: =F40-G40 -> #N/A | K40: =(E40)/(1+$H$4)^(D40-2025) -> #N/A | L40: =E40 -> #N/A
D41: =D40+1 -> 2036 | E41: =Financials!FA80 -> #N/A | F41: =F40*(1+$D$9) -> #N/A | G41: =_xlfn.XLOOKUP(D41,Amort!$A$3:$A$485,Amort!$C$3:$C$485) -> #N/A | H41: =F41-G41 -> #N/A | K41: =(E41)/(1+$H$4)^(D41-2025)+(F41)/(1+$H$4)^(D41-2025)-H8 -> #N/A | L41: =E41+F41 -> #N/A

Sheet FP3 Amort
C1: MORTGAGE
A2: Year | B2: Month | C2: Rate | D2: Payment | E2: Interest | F2: Principal | G2: Balance | H2: + | I2: Taxes | J2: PMI | K2: Insurance | L2: Total | M2: Notes
A3: =YEAR(B3) -> 2022 | B3: 44562 | C3: 0 | G3: 0
A4: =YEAR(B4) -> 2022 | B4: =EDATE(B3,1) -> 44593 | C4: 0.0369 | G4: 647200 | O4: 2022 | P4: Annually | Q4: Monthly | R4: YoY Inc.
A5: =YEAR(B5) -> 2022 | B5: =EDATE(B4,1) -> 44621 | C5: =C4 -> 0.0369 | G5: =G4 -> 647200 | O5: Taxes | P5: 3078.65 | Q5: =P5/12 -> 256.55417 | R5: 0.03
A6: =YEAR(B6) -> 2022 | B6: =EDATE(B5,1) -> 44652 | C6: =C5 -> 0.0369 | G6: =G5 -> 647200 | I6: =$P$5/12 -> 256.55417 | K6: =$P$7/12 -> 78.445 | L6: =SUM(I6:K6,D6) -> 334.99917 | O6: PMI | P6: =Q6*12 -> 588 | Q6: 49
A7: =YEAR(B7) -> 2022 | B7: =EDATE(B6,1) -> 44682 | C7: =C6 -> 0.0369 | D7: =-PMT($C$4/12,360,$G$4) -> 2975.2921 | E7: =G6*C6/12 -> 1990.14 | F7: =D7-E7 -> 985.15208 | G7: =IF(G6-F7<0,,G6-F7) -> 646214.85 | I7: =$P$5/12 -> 256.55417 | J7: =$P$6/12 -> 49 | K7: =$P$7/12 -> 78.445 | L7: =SUM(I7:K7,D7) -> 3359.2912 | O7: Hazard insurance | P7: 941.34 | Q7: =P7/12 -> 78.445 | R7: 0.03
A8: =YEAR(B8) -> 2022 | B8: =EDATE(B7,1) -> 44713 | C8: =C7 -> 0.0369 | D8: =IF(G7<=0,0,D7) -> 2975.2921 | E8: =G7*C7/12 -> 1987.1107 | F8: =D8-E8 -> 988.18142 | G8: =IF(G7-F8<0,,G7-F8) -> 645226.67 | I8: =$P$5/12 -> 256.55417 | J8: =$P$6/12 -> 49 | K8: =$P$7/12 -> 78.445 | L8: =SUM(I8:K8,D8) -> 3359.2912
A9: =YEAR(B9) -> 2022 | B9: =EDATE(B8,1) -> 44743 | C9: =C8 -> 0.0369 | D9: =IF(G8<=0,0,D8) -> 2975.2921 | E9: =G8*C8/12 -> 1984.072 | F9: =D9-E9 -> 991.22008 | G9: =IF(G8-F9<0,,G8-F9) -> 644235.45 | I9: =$P$5/12 -> 256.55417 | J9: =$P$6/12 -> 49 | K9: =$P$7/12 -> 78.445 | L9: =SUM(I9:K9,D9) -> 3359.2912
A10: =YEAR(B10) -> 2022 | B10: =EDATE(B9,1) -> 44774 | C10: =C9 -> 0.0369 | D10: =IF(G9<=0,0,D9) -> 2975.2921 | E10: =G9*C9/12 -> 1981.024 | F10: =D10-E10 -> 994.26808 | G10: =IF(G9-F10<0,,G9-F10) -> 643241.18 | I10: =$P$5/12 -> 256.55417 | J10: =$P$6/12 -> 49 | K10: =$P$7/12 -> 78.445 | L10: =SUM(I10:K10,D10) -> 3359.2912
A11: =YEAR(B11) -> 2022 | B11: =EDATE(B10,1) -> 44805 | C11: =C10 -> 0.0369 | D11: =IF(G10<=0,0,D10) -> 2975.2921 | E11: =G10*C10/12 -> 1977.9666 | F11: =D11-E11 -> 997.32545 | G11: =IF(G10-F11<0,,G10-F11) -> 642243.85 | I11: =$P$5/12 -> 256.55417 | J11: =$P$6/12 -> 49 | K11: =$P$7/12 -> 78.445 | L11: =SUM(I11:K11,D11) -> 3359.2912
A12: =YEAR(B12) -> 2022 | B12: =EDATE(B11,1) -> 44835 | C12: =C11 -> 0.0369 | D12: =IF(G11<=0,0,D11) -> 2975.2921 | E12: =G11*C11/12 -> 1974.8998 | F12: =D12-E12 -> 1000.3922 | G12: =IF(G11-F12<0,,G11-F12) -> 641243.46 | I12: =$P$5/12 -> 256.55417 | J12: =$P$6/12 -> 49 | K12: =$P$7/12 -> 78.445 | L12: =SUM(I12:K12,D12) -> 3359.2912
A13: =YEAR(B13) -> 2022 | B13: =EDATE(B12,1) -> 44866 | C13: =C12 -> 0.0369 | D13: =IF(G12<=0,0,D12) -> 2975.2921 | E13: =G12*C12/12 -> 1971.8236 | F13: =D13-E13 -> 1003.4684 | G13: =IF(G12-F13<0,,G12-F13) -> 640239.99 | I13: =$P$5/12 -> 256.55417 | J13: =$P$6/12 -> 49 | K13: =$P$7/12 -> 78.445 | L13: =SUM(I13:K13,D13) -> 3359.2912
A14: =YEAR(B14) -> 2022 | B14: =EDATE(B13,1) -> 44896 | C14: =C13 -> 0.0369 | D14: =IF(G13<=0,0,D13) -> 2975.2921 | E14: =G13*C13/12 -> 1968.738 | F14: =D14-E14 -> 1006.5541 | G14: =IF(G13-F14<0,,G13-F14) -> 639233.44 | I14: =$P$5/12 -> 256.55417 | J14: =$P$6/12 -> 49 | K14: =$P$7/12 -> 78.445 | L14: =SUM(I14:K14,D14) -> 3359.2912
A15: =YEAR(B15) -> 2023 | B15: =EDATE(B14,1) -> 44927 | C15: =C14 -> 0.0369 | D15: =IF(G14<=0,0,D14) -> 2975.2921 | E15: =G14*C14/12 -> 1965.6428 | F15: =D15-E15 -> 1009.6493 | G15: =IF(G14-F15<0,,G14-F15) -> 638223.79 | I15: =$Q$5*(1+$R$5)^(YEAR(B15)-$O$4)+53 -> 317.25079 | J15: =$P$6/12 -> 49 | K15: =K14*(1+$R$7)^(YEAR(B15)-YEAR(B14)) -> 80.79835 | L15: =SUM(I15:K15,D15) -> 3422.3412
A16: =YEAR(B16) -> 2023 | B16: =EDATE(B15,1) -> 44958 | C16: =C15 -> 0.0369 | D16: =IF(G15<=0,0,D15) -> 2975.2921 | E16: =G15*C15/12 -> 1962.5382 | F16: =D16-E16 -> 1012.7539 | G16: =IF(G15-F16<0,,G15-F16) -> 637211.03 | I16: =I15*(1+$R$5)^(YEAR(B16)-YEAR(B15)) -> 317.25079 | J16: =$P$6/12 -> 49 | K16: =K15*(1+$R$7)^(YEAR(B16)-YEAR(B15)) -> 80.79835 | L16: =SUM(I16:K16,D16) -> 3422.3412
A17: =YEAR(B17) -> 2023 | B17: =EDATE(B16,1) -> 44986 | C17: =C16 -> 0.0369 | D17: =IF(G16<=0,0,D16) -> 2975.2921 | E17: =G16*C16/12 -> 1959.4239 | F17: =D17-E17 -> 1015.8681 | G17: =IF(G16-F17<0,,G16-F17) -> 636195.17 | I17: =I16*(1+$R$5)^(YEAR(B17)-YEAR(B16)) -> 317.25079 | J17: =$P$6/12 -> 49 | K17: =K16*(1+$R$7)^(YEAR(B17)-YEAR(B16)) -> 80.79835 | L17: =SUM(I17:K17,D17) -> 3422.3412
A18: =YEAR(B18) -> 2023 | B18: =EDATE(B17,1) -> 45017 | C18: =C17 -> 0.0369 | D18: =IF(G17<=0,0,D17) -> 2975.2921 | E18: =G17*C17/12 -> 1956.3001 | F18: =D18-E18 -> 1018.9919 | G18: =IF(G17-F18<0,,G17-F18) -> 635176.17 | I18: =I17*(1+$R$5)^(YEAR(B18)-YEAR(B17)) -> 317.25079 | J18: =$P$6/12 -> 49 | K18: =K17*(1+$R$7)^(YEAR(B18)-YEAR(B17)) -> 80.79835 | L18: =SUM(I18:K18,D18) -> 3422.3412
A19: =YEAR(B19) -> 2023 | B19: =EDATE(B18,1) -> 45047 | C19: =C18 -> 0.0369 | D19: =IF(G18<=0,0,D18) -> 2975.2921 | E19: =G18*C18/12 -> 1953.1667 | F19: =D19-E19 -> 1022.1253 | G19: =IF(G18-F19<0,,G18-F19) -> 634154.05 | I19: =I18*(1+$R$5)^(YEAR(B19)-YEAR(B18)) -> 317.25079 | J19: =$P$6/12 -> 49 | K19: =K18*(1+$R$7)^(YEAR(B19)-YEAR(B18)) -> 80.79835 | L19: =SUM(I19:K19,D19) -> 3422.3412
A20: =YEAR(B20) -> 2023 | B20: =EDATE(B19,1) -> 45078 | C20: =C19 -> 0.0369 | D20: =IF(G19<=0,0,D19) -> 2975.2921 | E20: =G19*C19/12 -> 1950.0237 | F20: =D20-E20 -> 1025.2684 | G20: =IF(G19-F20<0,,G19-F20) -> 633128.78 | I20: =I19*(1+$R$5)^(YEAR(B20)-YEAR(B19)) -> 317.25079 | J20: =$P$6/12 -> 49 | K20: =K19*(1+$R$7)^(YEAR(B20)-YEAR(B19)) -> 80.79835 | L20: =SUM(I20:K20,D20) -> 3422.3412
A21: =YEAR(B21) -> 2023 | B21: =EDATE(B20,1) -> 45108 | C21: =C20 -> 0.0369 | D21: =IF(G20<=0,0,D20) -> 2975.2921 | E21: =G20*C20/12 -> 1946.871 | F21: =D21-E21 -> 1028.4211 | G21: =IF(G20-F21<0,,G20-F21) -> 632100.36 | I21: =I20*(1+$R$5)^(YEAR(B21)-YEAR(B20)) -> 317.25079 | J21: =$P$6/12 -> 49 | K21: =K20*(1+$R$7)^(YEAR(B21)-YEAR(B20)) -> 80.79835 | L21: =SUM(I21:K21,D21) -> 3422.3412
A22: =YEAR(B22) -> 2023 | B22: =EDATE(B21,1) -> 45139 | C22: =C21 -> 0.0369 | D22: =IF(G21<=0,0,D21) -> 2975.2921 | E22: =G21*C21/12 -> 1943.7086 | F22: =D22-E22 -> 1031.5835 | G22: =IF(G21-F22<0,,G21-F22) -> 631068.78 | I22: =I21*(1+$R$5)^(YEAR(B22)-YEAR(B21)) -> 317.25079 | J22: =$P$6/12 -> 49 | K22: =K21*(1+$R$7)^(YEAR(B22)-YEAR(B21)) -> 80.79835 | L22: =SUM(I22:K22,D22) -> 3422.3412
A23: =YEAR(B23) -> 2023 | B23: =EDATE(B22,1) -> 45170 | C23: =C22 -> 0.0369 | D23: =IF(G22<=0,0,D22) -> 2975.2921 | E23: =G22*C22/12 -> 1940.5365 | F23: =D23-E23 -> 1034.7556 | G23: =IF(G22-F23<0,,G22-F23) -> 630034.02 | I23: =I22*(1+$R$5)^(YEAR(B23)-YEAR(B22)) -> 317.25079 | J23: =$P$6/12 -> 49 | K23: =K22*(1+$R$7)^(YEAR(B23)-YEAR(B22)) -> 80.79835 | L23: =SUM(I23:K23,D23) -> 3422.3412
A24: =YEAR(B24) -> 2023 | B24: =EDATE(B23,1) -> 45200 | C24: =C23 -> 0.0369 | D24: =IF(G23<=0,0,D23) -> 2975.2921 | E24: =G23*C23/12 -> 1937.3546 | F24: =D24-E24 -> 1037.9375 | G24: =IF(G23-F24<0,,G23-F24) -> 628996.08 | I24: =I23*(1+$R$5)^(YEAR(B24)-YEAR(B23)) -> 317.25079 | J24: =$P$6/12 -> 49 | K24: =K23*(1+$R$7)^(YEAR(B24)-YEAR(B23)) -> 80.79835 | L24: =SUM(I24:K24,D24) -> 3422.3412
A25: =YEAR(B25) -> 2023 | B25: =EDATE(B24,1) -> 45231 | C25: =C24 -> 0.0369 | D25: =IF(G24<=0,0,D24) -> 2975.2921 | E25: =G24*C24/12 -> 1934.163 | F25: =D25-E25 -> 1041.1291 | G25: =IF(G24-F25<0,,G24-F25) -> 627954.95 | I25: =I24*(1+$R$5)^(YEAR(B25)-YEAR(B24)) -> 317.25079 | J25: =$P$6/12 -> 49 | K25: =K24*(1+$R$7)^(YEAR(B25)-YEAR(B24)) -> 80.79835 | L25: =SUM(I25:K25,D25) -> 3422.3412
A26: =YEAR(B26) -> 2023 | B26: =EDATE(B25,1) -> 45261 | C26: =C25 -> 0.0369 | D26: =IF(G25<=0,0,D25) -> 2975.2921 | E26: =G25*C25/12 -> 1930.9615 | F26: =D26-E26 -> 1044.3306 | G26: =IF(G25-F26<0,,G25-F26) -> 626910.62 | I26: =I25*(1+$R$5)^(YEAR(B26)-YEAR(B25)) -> 317.25079 | J26: =$P$6/12 -> 49 | K26: =K25*(1+$R$7)^(YEAR(B26)-YEAR(B25)) -> 80.79835 | L26: =SUM(I26:K26,D26) -> 3422.3412
A27: =YEAR(B27) -> 2024 | B27: =EDATE(B26,1) -> 45292 | C27: =C26 -> 0.0369 | D27: =IF(G26<=0,0,D26) -> 2975.2921 | E27: =G26*C26/12 -> 1927.7502 | F27: =D27-E27 -> 1047.5419 | G27: =IF(G26-F27<0,,G26-F27) -> 625863.08 | I27: =I26*(1+$R$5)^(YEAR(B27)-YEAR(B26)) -> 326.76832 | J27: =$P$6/12 -> 49 | K27: =K26*(1+$R$7)^(YEAR(B27)-YEAR(B26)) -> 83.222301 | L27: =SUM(I27:K27,D27) -> 3434.2827
... A389: =YEAR(B389) -> 2054 | B389: =EDATE(B388,1) -> 56309 | C389: =C388 -> 0.0369 | D389: =IF(G388<=0,0,D388) -> 0 | E389: =G388*C388/12 -> 0 | F389: =D389-E389 -> 0 | G389: =IF(G388-F389<0,,G388-F389) -> 0 | I389: =I388*(1+$R$5)^(YEAR(B389)-YEAR(B388)) -> 793.15247 | J389: =$P$6/12 -> 49 | K389: =K388*(1+$R$7)^(YEAR(B389)-YEAR(B388)) -> 202.00237 | L389: =SUM(I389:K389,D389) -> 1044.1548

Sheet Amort
C1: MORTGAGE | H1: 2ND LOAN
A2: Yr | C2: Balance | D2: Interest | E2: Principal | F2: Payment | H2: Balance | I2: Interest | J2: Principal | K2: Payment
A3: =YEAR(B3) -> 2025 | B3: =Financials!B1 -> 45658 | C3: =ROUND(Inputs!$B$11-Inputs!$B$13,2) -> #N/A | D3: =IF($C3<>0,Inputs!$B$14/12*C3,0) -> #N/A | E3: =F3-D3 -> #N/A | F3: =IF($C3>0,-PMT(Inputs!$B$14/12,Inputs!$B$15,Inputs!$B$11-Inputs!$B$13),0) -> #N/A | H3: =ROUND(Inputs!$B$27,2) -> 0 | I3: =IF($H3<>0,Inputs!$B$28/12*H3,0) -> 0 | J3: =K3-I3 -> 0 | K3: =H3*600/100000 -> 0
A4: =YEAR(B4) -> 2025 | B4: =EDATE(B3,1) -> 45689 | C4: =IF(C3>0,C3-E3,0) -> #N/A | D4: =IF($C4<>0,Inputs!$B$14/12*C4,0) -> #N/A | E4: =F4-D4 -> #N/A | F4: =IF($C4>0,-PMT(Inputs!$B$14/12,Inputs!$B$15,Inputs!$B$11-Inputs!$B$13),0) -> #N/A | H4: =IF(H3>0,H3-J3,0) -> 0 | I4: =IF($H4<>0,Inputs!$B$28/12*H4,0) -> 0 | J4: =K4-I4 -> 0 | K4: =IF(H4>0,IF(H4+I4>K3,K3,H4+I4),0) -> 0
A5: =YEAR(B5) -> 2025 | B5: =EDATE(B4,1) -> 45717 | C5: =IF(C4>0,C4-E4,0) -> #N/A | D5: =IF($C5<>0,Inputs!$B$14/12*C5,0) -> #N/A | E5: =F5-D5 -> #N/A | F5: =IF($C5>0,-PMT(Inputs!$B$14/12,Inputs!$B$15,Inputs!$B$11-Inputs!$B$13),0) -> #N/A | H5: =IF(H4>0,H4-J4,0) -> 0 | I5: =IF($H5<>0,Inputs!$B$28/12*H5,0) -> 0 | J5: =K5-I5 -> 0 | K5: =IF(H5>0,IF(H5+I5>K4,K4,H5+I5),0) -> 0
A6: =YEAR(B6) -> 2025 | B6: =EDATE(B5,1) -> 45748 | C6: =IF(C5>0,C5-E5,0) -> #N/A | D6: =IF($C6<>0,Inputs!$B$14/12*C6,0) -> #N/A | E6: =F6-D6 -> #N/A | F6: =IF($C6>0,-PMT(Inputs!$B$14/12,Inputs!$B$15,Inputs!$B$11-Inputs!$B$13),0) -> #N/A | H6: =IF(H5>0,H5-J5,0) -> 0 | I6: =IF($H6<>0,Inputs!$B$28/12*H6,0) -> 0 | J6: =K6-I6 -> 0 | K6: =IF(H6>0,IF(H6+I6>K5,K5,H6+I6),0) -> 0
A7: =YEAR(B7) -> 2025 | B7: =EDATE(B6,1) -> 45778 | C7: =IF(C6>0,C6-E6,0) -> #N/A | D7: =IF($C7<>0,Inputs!$B$14/12*C7,0) -> #N/A | E7: =F7-D7 -> #N/A | F7: =IF($C7>0,-PMT(Inputs!$B$14/12,Inputs!$B$15,Inputs!$B$11-Inputs!$B$13),0) -> #N/A | H7: =IF(H6>0,H6-J6,0) -> 0 | I7: =IF($H7<>0,Inputs!$B$28/12*H7,0) -> 0 | J7: =K7-I7 -> 0 | K7: =IF(H7>0,IF(H7+I7>K6,K6,H7+I7),0) -> 0
A8: =YEAR(B8) -> 2025 | B8: =EDATE(B7,1) -> 45809 | C8: =IF(C7>0,C7-E7,0) -> #N/A | D8: =IF($C8<>0,Inputs!$B$14/12*C8,0) -> #N/A | E8: =F8-D8 -> #N/A | F8: =IF($C8>0,-PMT(Inputs!$B$14/12,Inputs!$B$15,Inputs!$B$11-Inputs!$B$13),0) -> #N/A | H8: =IF(H7>0,H7-J7,0) -> 0 | I8: =IF($H8<>0,Inputs!$B$28/12*H8,0) -> 0 | J8: =K8-I8 -> 0 | K8: =IF(H8>0,IF(H8+I8>K7,K7,H8+I8),0) -> 0
A9: =YEAR(B9) -> 2025 | B9: =EDATE(B8,1) -> 45839 | C9: =IF(C8>0,C8-E8,0) -> #N/A | D9: =IF($C9<>0,Inputs!$B$14/12*C9,0) -> #N/A | E9: =F9-D9 -> #N/A | F9: =IF($C9>0,-PMT(Inputs!$B$14/12,Inputs!$B$15,Inputs!$B$11-Inputs!$B$13),0) -> #N/A | H9: =IF(H8>0,H8-J8,0) -> 0 | I9: =IF($H9<>0,Inputs!$B$28/12*H9,0) -> 0 | J9: =K9-I9 -> 0 | K9: =IF(H9>0,IF(H9+I9>K8,K8,H9+I9),0) -> 0
A10: =YEAR(B10) -> 2025 | B10: =EDATE(B9,1) -> 45870 | C10: =IF(C9>0,C9-E9,0) -> #N/A | D10: =IF($C10<>0,Inputs!$B$14/12*C10,0) -> #N/A | E10: =F10-D10 -> #N/A | F10: =IF($C10>0,-PMT(Inputs!$B$14/12,Inputs!$B$15,Inputs!$B$11-Inputs!$B$13),0) -> #N/A | H10: =IF(H9>0,H9-J9,0) -> 0 | I10: =IF($H10<>0,Inputs!$B$28/12*H10,0) -> 0 | J10: =K10-I10 -> 0 | K10: =IF(H10>0,IF(H10+I10>K9,K9,H10+I10),0) -> 0
A11: =YEAR(B11) -> 2025 | B11: =EDATE(B10,1) -> 45901 | C11: =IF(C10>0,C10-E10,0) -> #N/A | D11: =IF($C11<>0,Inputs!$B$14/12*C11,0) -> #N/A | E11: =F11-D11 -> #N/A | F11: =IF($C11>0,-PMT(Inputs!$B$14/12,Inputs!$B$15,Inputs!$B$11-Inputs!$B$13),0) -> #N/A | H11: =IF(H10>0,H10-J10,0) -> 0 | I11: =IF($H11<>0,Inputs!$B$28/12*H11,0) -> 0 | J11: =K11-I11 -> 0 | K11: =IF(H11>0,IF(H11+I11>K10,K10,H11+I11),0) -> 0
A12: =YEAR(B12) -> 2025 | B12: =EDATE(B11,1) -> 45931 | C12: =IF(C11>0,C11-E11,0) -> #N/A | D12: =IF($C12<>0,Inputs!$B$14/12*C12,0) -> #N/A | E12: =F12-D12 -> #N/A | F12: =IF($C12>0,-PMT(Inputs!$B$14/12,Inputs!$B$15,Inputs!$B$11-Inputs!$B$13),0) -> #N/A | H12: =IF(H11>0,H11-J11,0) -> 0 | I12: =IF($H12<>0,Inputs!$B$28/12*H12,0) -> 0 | J12: =K12-I12 -> 0 | K12: =IF(H12>0,IF(H12+I12>K11,K11,H12+I12),0) -> 0
A13: =YEAR(B13) -> 2025 | B13: =EDATE(B12,1) -> 45962 | C13: =IF(C12>0,C12-E12,0) -> #N/A | D13: =IF($C13<>0,Inputs!$B$14/12*C13,0) -> #N/A | E13: =F13-D13 -> #N/A | F13: =IF($C13>0,-PMT(Inputs!$B$14/12,Inputs!$B$15,Inputs!$B$11-Inputs!$B$13),0) -> #N/A | H13: =IF(H12>0,H12-J12,0) -> 0 | I13: =IF($H13<>0,Inputs!$B$28/12*H13,0) -> 0 | J13: =K13-I13 -> 0 | K13: =IF(H13>0,IF(H13+I13>K12,K12,H13+I13),0) -> 0
A14: =YEAR(B14) -> 2025 | B14: =EDATE(B13,1) -> 45992 | C14: =IF(C13>0,C13-E13,0) -> #N/A | D14: =IF($C14<>0,Inputs!$B$14/12*C14,0) -> #N/A | E14: =F14-D14 -> #N/A | F14: =IF($C14>0,-PMT(Inputs!$B$14/12,Inputs!$B$15,Inputs!$B$11-Inputs!$B$13),0) -> #N/A | H14: =IF(H13>0,H13-J13,0) -> 0 | I14: =IF($H14<>0,Inputs!$B$28/12*H14,0) -> 0 | J14: =K14-I14 -> 0 | K14: =IF(H14>0,IF(H14+I14>K13,K13,H14+I14),0) -> 0
A15: =YEAR(B15) -> 2026 | B15: =EDATE(B14,1) -> 46023 | C15: =IF(C14>0,C14-E14,0) -> #N/A | D15: =IF($C15<>0,Inputs!$B$14/12*C15,0) -> #N/A | E15: =F15-D15 -> #N/A | F15: =IF($C15>0,-PMT(Inputs!$B$14/12,Inputs!$B$15,Inputs!$B$11-Inputs!$B$13),0) -> #N/A | H15: =IF(H14>0,H14-J14,0) -> 0 | I15: =IF($H15<>0,Inputs!$B$28/12*H15,0) -> 0 | J15: =K15-I15 -> 0 | K15: =IF(H15>0,IF(H15+I15>K14,K14,H15+I15),0) -> 0
... A485: =YEAR(B485) -> 2065 | B485: =EDATE(B484,1) -> 60327 | C485: =IF(C484>0,C484-E484,0) -> #N/A | D485: =IF($C485<>0,Inputs!$B$14/12*C485,0) -> #N/A | E485: =F485-D485 -> #N/A | F485: =IF($C485>0,-PMT(Inputs!$B$14/12,Inputs!$B$15,Inputs!$B$11-Inputs!$B$13),0) -> #N/A | H485: =IF(H484>0,H484-J484,0) -> 0 | I485: =IF($H485<>0,Inputs!$B$28/12*H485,0) -> 0 | J485: =K485-I485 -> 0 | K485: =IF(H485>0,IF(H485+I485>K484,K484,H485+I485),0) -> 0

Sheet Pivot
D1: Purchase price | E1: 970000 | G1: Capital | H1: 350000 | P1: 4plex Guess Price (filter) | Q1: 650000 | S1: Select | T1: Address | U1: Rent | V1: Notes
D2: Beds | E2: 8 | G2: Downpayment (%) | H2: 0.25 | N2: =825000/200 -> 4125 | P2: Purchase price reduction | Q2: 0.1 | S2: 1 | T2: 3334 S 825 E, Salt Lake City, UT 84106 | U2: =1525+1400+1235+1350+1350+1385 -> 8245 | V2: CapRate: 4.9%; GRM: 178.8
A3: beds | B3: (All) | D3: Monthly Rent | E3: =2400+1400+1450 -> 5250 | G3: pp | H3: =H1/H2 -> 1400000 | K3: Max Price | L3: PMT | P3: Buyer's Commission | Q3: 0 | S3: 0 | T3: 1309 Hidden Creek Ct, Salt Lake City, UT 84117 | U3: =1450+1525+1445+1470 -> 5890 | V3: CapRate: 5.6%; GRM: 156.5
A4: homeStatus | B4: (All) | D4: Calc Rent Mult | E4: =E1/(E2*660) -> 183.71212 | F4: =_xlfn.RANK.AVG(E4,H10:H94) -> #N/A | G4: Target GRM | H4: 200 | J4: Investment | K4: =300000/0.25 -> 1200000 | L4: =PMT(0.07/12,30*360,-K4*0.97*0.75) -> 5092.5 | P4: Decrease of Listing | Q4: =(Q7/(1-Q2))-Q7 -> #N/A | S4: 0 | T4: 1711 W 400 N, Salt Lake City, UT 84116 | U4: 6345 | V4: CapRate: 5.9%; GRM: 149.1 | W4: Rose Park
A5: homeType | B5: (All) | D5: Rent Multiplier | E5: =E1/E3 -> 184.7619 | G5: Rent | H5: =H3/H4 -> 7000 | J5: Personal Home | K5: =300000/0.15 -> 2000000 | L5: =PMT(0.07/12,30*360,-K5*0.97*0.95) -> 10750.833 | P5: ="CapRate: "&TEXT(Inputs!B47,"0.0%") -> #N/A | Q5: =Inputs!B47 -> #N/A | S5: 0 | T5: 827 E 100 S, Salt Lake City, UT 84102 | U5: =950+1100+1100+1100 -> 4250 | V5: CapRate: 5.0%; GRM: 164.1
A6: addressZipcode | B6: (All) | D6: Inv GRM | E6: =E3/(E1)*1000 -> 5.4123711 | G6: Units | H6: 4 | P6: ="GRM: "&TEXT(Inputs!B48,"0.0") -> #N/A | Q6: =Inputs!B48 -> #N/A | R6: =_xlfn.TEXTJOIN("; ",TRUE,P5:P6) -> #N/A | S6: 0 | T6: 311 E 3360 S, Salt Lake City, UT 84115 | U6: =1500*4 -> 6000 | V6: CapRate: 4.1%; GRM: 188.6
A7: 4plex est? | B7: 1 | G7: Rent / Unit | H7: =H5/H6 -> 1750 | P7: PP | Q7: =Inputs!B11 -> #N/A
A9: address | B9: city_tag | C9: addressCity | D9: detailUrl | E9: unformattedPrice | F9: rentZestimate | G9: Sum of Rent Est. | H9: Sum of beds | I9: Sum of ReqDwnPmt | J9: Sum of Taxes | K9: Sum of Insurance | L9: Sum of DaysOnZillow | M9: Sum of SqFtMulti | N9: Sum of AvgRentMulti | O9: Select | P9: Rent Override | Q9: Rent | R9: Notes | S9: 0 | T9: 288 E 10th Ave, Salt Lake City, UT 84103 | U9: =1775+1295+1025+895 -> 4990 | V9: CapRate: 3.0%; GRM: 238.1
A10: 351 S 300 E, Salt Lake City, UT 84111 | B10: Salt Lake City | C10: Salt Lake City | D10: https://www.zillow.com/homedetails/351-S-300-E-Salt-Lake-City-UT-84111/141869764_zpid/ | E10: 700000 | F10: 1488 | G10: 3960 | H10: 6 | I10: 175000 | J10: 344.16667 | K10: 250.83333 | L10: 34.06522 | M10: 200 | N10: 332.43728 | O10: =IFERROR(_xlfn.XLOOKUP(A10,$T$1:$T$13,$S$1:$S$13,,0),0) -> 0 | P10: =IFERROR(_xlfn.XLOOKUP(A10,$T$1:$T$13,$U$1:$U$13,,0),0) -> 0 | Q10: =IF(P10>1,P10,G10) -> 3960 | R10: =IFERROR(_xlfn.XLOOKUP(A10,$T$1:$T$13,$V$1:$V$13,,0),0) -> 0 | S10: 0 | T10: 64 N F St, Salt Lake City, UT 84103 | U10: =1500+1215+1800 -> 4515 | V10: CapRate: 3.8%; GRM: 207.1
A11: 435 S 900 W, Salt Lake City, UT 84104 | B11: Salt Lake City | C11: Salt Lake City | D11: https://www.zillow.com/homedetails/435-S-900-W-Salt-Lake-City-UT-84104/339788697_zpid/ | E11: 789900 | F11: 1645 | G11: 4620 | H11: 7 | I11: 197475 | J11: 388.3675 | K11: 283.0475 | L11: 89.064444 | M11: 216.47027 | N11: 334.1269 | O11: =IFERROR(_xlfn.XLOOKUP(A11,$T$1:$T$13,$S$1:$S$13,,0),0) -> 0 | P11: =IFERROR(_xlfn.XLOOKUP(A11,$T$1:$T$13,$U$1:$U$13,,0),0) -> 0 | Q11: =IF(P11>1,P11,G11) -> 4620 | R11: =IFERROR(_xlfn.XLOOKUP(A11,$T$1:$T$13,$V$1:$V$13,,0),0) -> 0 | S11: 0 | T11: 2269 S Green St #1-4, Salt Lake City, UT 84106 | U11: =575+1650+900+800 -> 3925 | V11: CapRate: 4.6%; GRM: 187.8
A12: 509 E 800 S, Salt Lake City, UT 84102 | B12: Salt Lake City | C12: Salt Lake City | D12: https://www.zillow.com/homedetails/509-E-800-S-Salt-Lake-City-UT-84102/305058100_zpid/ | E12: 749000 | F12: 2725 | G12: 2640 | H12: 4 | I12: 187250 | J12: 368.25833 | K12: 268.39167 | L12: 25.073032 | M12: 225.33093 | N12: 293.47286 | O12: =IFERROR(_xlfn.XLOOKUP(A12,$T$1:$T$13,$S$1:$S$13,,0),0) -> 0 | P12: =IFERROR(_xlfn.XLOOKUP(A12,$T$1:$T$13,$U$1:$U$13,,0),0) -> 0 | Q12: =IF(P12>1,P12,G12) -> 2640 | R12: =IFERROR(_xlfn.XLOOKUP(A12,$T$1:$T$13,$V$1:$V$13,,0),0) -> 0 | S12: 0 | T12: 423 E 1st Ave, Salt Lake City, UT 84103 | U12: =1210+1140+1290 -> 3640 | V12: CapRate: 3.9%; GRM: 186.3
A13: 606 W North Temple, Salt Lake City, UT 84116 | B13: Salt Lake City | C13: Salt Lake City | D13: https://www.zillow.com/homedetails/606-W-North-Temple-Salt-Lake-City-UT-84116/446037534_zpid/ | E13: 6750000 | F13: (blank) | G13: 14520 | H13: 22 | I13: 1687500 | J13: 3318.75 | K13: 2418.75 | L13: 72.065243 | M13: 228.32595 | N13: 511.36364 | O13: =IFERROR(_xlfn.XLOOKUP(A13,$T$1:$T$13,$S$1:$S$13,,0),0) -> 0 | P13: =IFERROR(_xlfn.XLOOKUP(A13,$T$1:$T$13,$U$1:$U$13,,0),0) -> 0 | Q13: =IF(P13>1,P13,G13) -> 14520 | R13: =IFERROR(_xlfn.XLOOKUP(A13,$T$1:$T$13,$V$1:$V$13,,0),0) -> 0 | S13: 0 | T13: 152 E 3rd Ave N, Salt Lake City, UT 84103 | U13: =2700+1800 -> 4500 | V13: =R6 -> #N/A
A14: 228 S 900 E, Salt Lake City, UT 84102 | B14: Salt Lake City | C14: Salt Lake City | D14: https://www.zillow.com/homedetails/228-S-900-E-Salt-Lake-City-UT-84102/2069452025_zpid/ | E14: 1799000 | F14: 2041 | G14: 10560 | H14: 16 | I14: 449750 | J14: 884.50833 | K14: 644.64167 | L14: 187.0808 | M14: 230.8482 | N14: 534.41325 | O14: =IFERROR(_xlfn.XLOOKUP(A14,$T$1:$T$13,$S$1:$S$13,,0),0) -> 0 | P14: =IFERROR(_xlfn.XLOOKUP(A14,$T$1:$T$13,$U$1:$U$13,,0),0) -> 0 | Q14: =IF(P14>1,P14,G14) -> 10560 | R14: =IFERROR(_xlfn.XLOOKUP(A14,$T$1:$T$13,$V$1:$V$13,,0),0) -> 0
A15: 275 W 500 N, Salt Lake City, UT 84103 | B15: Salt Lake City | C15: Salt Lake City | D15: https://www.zillow.com/homedetails/275-W-500-N-Salt-Lake-City-UT-84103/2086478311_zpid/ | E15: 835000 | F15: 2245 | G15: 3960 | H15: 6 | I15: 208750 | J15: 410.54167 | K15: 299.20833 | L15: 213.06398 | M15: 234.74838 | N15: 301.94104 | O15: =IFERROR(_xlfn.XLOOKUP(A15,$T$1:$T$13,$S$1:$S$13,,0),0) -> 0 | P15: =IFERROR(_xlfn.XLOOKUP(A15,$T$1:$T$13,$U$1:$U$13,,0),0) -> 0 | Q15: =IF(P15>1,P15,G15) -> 3960 | R15: =IFERROR(_xlfn.XLOOKUP(A15,$T$1:$T$13,$V$1:$V$13,,0),0) -> 0
A16: 1019 E 1700 S, Salt Lake City, UT 84105 | B16: Salt Lake City | C16: Salt Lake City | D16: https://www.zillow.com/homedetails/1019-E-1700-S-Salt-Lake-City-UT-84105/350304499_zpid/ | E16: 1250000 | F16: 2712 | G16: 3960 | H16: 6 | I16: 312500 | J16: 614.58333 | K16: 447.91667 | L16: 104.06566 | M16: 239.69319 | N16: 404.06834 | O16: =IFERROR(_xlfn.XLOOKUP(A16,$T$1:$T$13,$S$1:$S$13,,0),0) -> 0 | P16: =IFERROR(_xlfn.XLOOKUP(A16,$T$1:$T$13,$U$1:$U$13,,0),0) -> 0 | Q16: =IF(P16>1,P16,G16) -> 3960 | R16: =IFERROR(_xlfn.XLOOKUP(A16,$T$1:$T$13,$V$1:$V$13,,0),0) -> 0
A17: 1162 E 400 S, Salt Lake City, UT 84102 | B17: Salt Lake City | C17: Salt Lake City | D17: https://www.zillow.com/homedetails/1162-E-400-S-Salt-Lake-City-UT-84102/2057508524_zpid/ | E17: 2300000 | F17: 1863 | G17: 10560 | H17: 16 | I17: 575000 | J17: 1130.8333 | K17: 824.16667 | L17: 240.06345 | M17: 240.5103 | N17: 737.07562 | O17: =IFERROR(_xlfn.XLOOKUP(A17,$T$1:$T$13,$S$1:$S$13,,0),0) -> 0 | P17: =IFERROR(_xlfn.XLOOKUP(A17,$T$1:$T$13,$U$1:$U$13,,0),0) -> 0 | Q17: =IF(P17>1,P17,G17) -> 10560 | R17: =IFERROR(_xlfn.XLOOKUP(A17,$T$1:$T$13,$V$1:$V$13,,0),0) -> 0
A18: 1612 S 500 E, Salt Lake City, UT 84105 | B18: Salt Lake City | C18: Salt Lake City | D18: https://www.zillow.com/homedetails/1612-S-500-E-Salt-Lake-City-UT-84105/12772179_zpid/ | E18: 724900 | F18: 2193 | G18: 5280 | H18: 8 | I18: 181225 | J18: 356.40917 | K18: 259.75583 | L18: 83.064248 | M18: 241.63333 | N18: 240.78629 | O18: =IFERROR(_xlfn.XLOOKUP(A18,$T$1:$T$13,$S$1:$S$13,,0),0) -> 0 | P18: =IFERROR(_xlfn.XLOOKUP(A18,$T$1:$T$13,$U$1:$U$13,,0),0) -> 0 | Q18: =IF(P18>1,P18,G18) -> 5280 | R18: =IFERROR(_xlfn.XLOOKUP(A18,$T$1:$T$13,$V$1:$V$13,,0),0) -> 0
A19: 1155 E 200 S, Salt Lake City, UT 84102 | B19: Salt Lake City | C19: Salt Lake City | D19: https://www.zillow.com/homedetails/1155-E-200-S-Salt-Lake-City-UT-84102/457834492_zpid/ | E19: 5300000 | F19: (blank) | G19: 15840 | H19: 24 | I19: 1325000 | J19: 2605.8333 | K19: 1899.1667 | L19: 18.064363 | M19: 243.34252 | N19: 368.05556 | O19: =IFERROR(_xlfn.XLOOKUP(A19,$T$1:$T$13,$S$1:$S$13,,0),0) -> 0 | P19: =IFERROR(_xlfn.XLOOKUP(A19,$T$1:$T$13,$U$1:$U$13,,0),0) -> 0 | Q19: =IF(P19>1,P19,G19) -> 15840 | R19: =IFERROR(_xlfn.XLOOKUP(A19,$T$1:$T$13,$V$1:$V$13,,0),0) -> 0
A20: 862 E Menlo Ave, Salt Lake City, UT 84102 | B20: Salt Lake City | C20: Salt Lake City | D20: https://www.zillow.com/homedetails/862-E-Menlo-Ave-Salt-Lake-City-UT-84102/12753475_zpid/ | E20: 699000 | F20: 2064 | G20: 4620 | H20: 7 | I20: 174750 | J20: 343.675 | K20: 250.475 | L20: 187.0808 | M20: 246.12676 | N20: 252.54568 | O20: =IFERROR(_xlfn.XLOOKUP(A20,$T$1:$T$13,$S$1:$S$13,,0),0) -> 0 | P20: =IFERROR(_xlfn.XLOOKUP(A20,$T$1:$T$13,$U$1:$U$13,,0),0) -> 0 | Q20: =IF(P20>1,P20,G20) -> 4620 | R20: =IFERROR(_xlfn.XLOOKUP(A20,$T$1:$T$13,$V$1:$V$13,,0),0) -> 0
A21: 2530 S Parkcrest Dr, West Valley City, UT 84119 | B21: Salt Lake City | C21: West Valley City | D21: https://www.zillow.com/homedetails/2530-S-Parkcrest-Dr-West-Valley-City-UT-84119/141854429_zpid/ | E21: 830000 | F21: 1555 | G21: 5280 | H21: 8 | I21: 207500 | J21: 408.08333 | K21: 297.41667 | L21: 26.064815 | M21: 246.14472 | N21: 353.33936 | O21: =IFERROR(_xlfn.XLOOKUP(A21,$T$1:$T$13,$S$1:$S$13,,0),0) -> 0 | P21: =IFERROR(_xlfn.XLOOKUP(A21,$T$1:$T$13,$U$1:$U$13,,0),0) -> 0 | Q21: =IF(P21>1,P21,G21) -> 5280 | R21: =IFERROR(_xlfn.XLOOKUP(A21,$T$1:$T$13,$V$1:$V$13,,0),0) -> 0
A22: 240 N Spencer Ct, Salt Lake City, UT 84103 | B22: Avenues | C22: Salt Lake City | D22: https://www.zillow.com/homedetails/240-N-Spencer-Ct-Salt-Lake-City-UT-84103/12718744_zpid/ | E22: 3699000 | F22: 2222 | G22: 19800 | H22: 30 | I22: 924750 | J22: 1818.675 | K22: 1325.475 | L22: 228.06343 | M22: 248.94004 | N22: 935.10824 | O22: =IFERROR(_xlfn.XLOOKUP(A22,$T$1:$T$13,$S$1:$S$13,,0),0) -> 0 | P22: =IFERROR(_xlfn.XLOOKUP(A22,$T$1:$T$13,$U$1:$U$13,,0),0) -> 0 | Q22: =IF(P22>1,P22,G22) -> 19800 | R22: =IFERROR(_xlfn.XLOOKUP(A22,$T$1:$T$13,$V$1:$V$13,,0),0) -> 0
A23: 416 E Scott Ave, Salt Lake City, UT 84115 | B23: Salt Lake City | C23: Salt Lake City | D23: https://www.zillow.com/homedetails/416-E-Scott-Ave-Salt-Lake-City-UT-84115/305059086_zpid/ | E23: 2200000 | F23: 1833 | G23: 11880 | H23: 18 | I23: 550000 | J23: 1081.6667 | K23: 788.33333 | L23: 167.06561 | M23: 253.9536 | N23: 701.96096 | O23: =IFERROR(_xlfn.XLOOKUP(A23,$T$1:$T$13,$S$1:$S$13,,0),0) -> 0 | P23: =IFERROR(_xlfn.XLOOKUP(A23,$T$1:$T$13,$U$1:$U$13,,0),0) -> 0 | Q23: =IF(P23>1,P23,G23) -> 11880 | R23: =IFERROR(_xlfn.XLOOKUP(A23,$T$1:$T$13,$V$1:$V$13,,0),0) -> 0
A24: 2870 W 3100 S, West Valley City, UT 84119 | B24: Salt Lake City | C24: West Valley City | D24: https://www.zillow.com/homedetails/2870-W-3100-S-West-Valley-City-UT-84119/12743620_zpid/ | E24: 869000 | F24: 2303 | G24: 4620 | H24: 7 | I24: 217250 | J24: 427.25833 | K24: 311.39167 | L24: 72.065579 | M24: 254.83871 | N24: 292.11934 | O24: =IFERROR(_xlfn.XLOOKUP(A24,$T$1:$T$13,$S$1:$S$13,,0),0) -> 0 | P24: =IFERROR(_xlfn.XLOOKUP(A24,$T$1:$T$13,$U$1:$U$13,,0),0) -> 0 | Q24: =IF(P24>1,P24,G24) -> 4620 | R24: =IFERROR(_xlfn.XLOOKUP(A24,$T$1:$T$13,$V$1:$V$13,,0),0) -> 0
A25: 1314 E Crandall Ave, Salt Lake City, UT 84106 | B25: Salt Lake City | C25: Salt Lake City | D25: https://www.zillow.com/homedetails/1314-E-Crandall-Ave-Salt-Lake-City-UT-84106/12783602_zpid/ | E25: 805000 | F25: 2234 | G25: 3960 | H25: 6 | I25: 201250 | J25: 395.79167 | K25: 288.45833 | L25: 81.065116 | M25: 259.84506 | N25: 291.97565 | O25: =IFERROR(_xlfn.XLOOKUP(A25,$T$1:$T$13,$S$1:$S$13,,0),0) -> 0 | P25: =IFERROR(_xlfn.XLOOKUP(A25,$T$1:$T$13,$U$1:$U$13,,0),0) -> 0 | Q25: =IF(P25>1,P25,G25) -> 3960 | R25: =IFERROR(_xlfn.XLOOKUP(A25,$T$1:$T$13,$V$1:$V$13,,0),0) -> 0
A26: 751 E Scott Ave, Millcreek, UT 84106 | B26: Millcreek | C26: Millcreek | D26: https://www.zillow.com/homedetails/751-E-Scott-Ave-Millcreek-UT-84106/305058922_zpid/ | E26: 1890000 | F26: 1761 | G26: 8580 | H26: 13 | I26: 472500 | J26: 929.25 | K26: 677.25 | L26: 177.06569 | M26: 261.77285 | N26: 657.78076 | O26: =IFERROR(_xlfn.XLOOKUP(A26,$T$1:$T$13,$S$1:$S$13,,0),0) -> 0 | P26: =IFERROR(_xlfn.XLOOKUP(A26,$T$1:$T$13,$U$1:$U$13,,0),0) -> 0 | Q26: =IF(P26>1,P26,G26) -> 8580 | R26: =IFERROR(_xlfn.XLOOKUP(A26,$T$1:$T$13,$V$1:$V$13,,0),0) -> 0
A27: 2754 W 3835 S, West Valley City, UT 84119 | B27: Salt Lake City | C27: West Valley City | D27: https://www.zillow.com/homedetails/2754-W-3835-S-West-Valley-City-UT-84119/333158912_zpid/ | E27: 800000 | F27: 1721 | G27: 3960 | H27: 6 | I27: 200000 | J27: 393.33333 | K27: 286.66667 | L27: 44.046771 | M27: 264.98841 | N27: 343.53412 | O27: =IFERROR(_xlfn.XLOOKUP(A27,$T$1:$T$13,$S$1:$S$13,,0),0) -> 0 | P27: =IFERROR(_xlfn.XLOOKUP(A27,$T$1:$T$13,$U$1:$U$13,,0),0) -> 0 | Q27: =IF(P27>1,P27,G27) -> 3960 | R27: =IFERROR(_xlfn.XLOOKUP(A27,$T$1:$T$13,$V$1:$V$13,,0),0) -> 0
A28: 64 N F St, Salt Lake City, UT 84103 | B28: Avenues | C28: Salt Lake City | D28: https://www.zillow.com/homedetails/64-N-F-St-Salt-Lake-City-UT-84103/305056275_zpid/ | E28: 960000 | F28: 2096 | G28: 3960 | H28: 6 | I28: 240000 | J28: 472 | K28: 344 | L28: 106.06528 | M28: 266.66667 | N28: 362.34097 | O28: =IFERROR(_xlfn.XLOOKUP(A28,$T$1:$T$13,$S$1:$S$13,,0),0) -> 0 | P28: =IFERROR(_xlfn.XLOOKUP(A28,$T$1:$T$13,$U$1:$U$13,,0),0) -> 4515 | Q28: =IF(P28>1,P28,G28) -> 4515 | R28: =IFERROR(_xlfn.XLOOKUP(A28,$T$1:$T$13,$V$1:$V$13,,0),0) -> CapRate: 3.8%; GRM: 207.1
A29: 745 S 600 E, Salt Lake City, UT 84102 | B29: Salt Lake City | C29: Salt Lake City | D29: https://www.zillow.com/homedetails/745-S-600-E-Salt-Lake-City-UT-84102/12756964_zpid/ | E29: 705000 | F29: 2125 | G29: 2640 | H29: 4 | I29: 176250 | J29: 346.625 | K29: 252.625 | L29: 113.06025 | M29: 268.46915 | N29: 312.75735 | O29: =IFERROR(_xlfn.XLOOKUP(A29,$T$1:$T$13,$S$1:$S$13,,0),0) -> 0 | P29: =IFERROR(_xlfn.XLOOKUP(A29,$T$1:$T$13,$U$1:$U$13,,0),0) -> 0 | Q29: =IF(P29>1,P29,G29) -> 2640 | R29: =IFERROR(_xlfn.XLOOKUP(A29,$T$1:$T$13,$V$1:$V$13,,0),0) -> 0
A30: 3532 S 900 E, Salt Lake City, UT 84106 | B30: Millcreek | C30: Salt Lake City | D30: https://www.zillow.com/homedetails/3532-S-900-E-Salt-Lake-City-UT-84106/2069834554_zpid/ | E30: 1900000 | F30: 3034 | G30: 3960 | H30: 6 | I30: 475000 | J30: 934.16667 | K30: 680.83333 | L30: 48.065463 | M30: 268.62717 | N30: 577.00688 | O30: =IFERROR(_xlfn.XLOOKUP(A30,$T$1:$T$13,$S$1:$S$13,,0),0) -> 0 | P30: =IFERROR(_xlfn.XLOOKUP(A30,$T$1:$T$13,$U$1:$U$13,,0),0) -> 0 | Q30: =IF(P30>1,P30,G30) -> 3960 | R30: =IFERROR(_xlfn.XLOOKUP(A30,$T$1:$T$13,$V$1:$V$13,,0),0) -> 0
A31: 1021 E Millbert Ave, Salt Lake City, UT 84106 | B31: Millcreek | C31: Salt Lake City | D31: https://www.zillow.com/homedetails/1021-E-Millbert-Ave-Salt-Lake-City-UT-84106/12790416_zpid/ | E31: 1140000 | F31: 2537 | G31: 5280 | H31: 8 | I31: 285000 | J31: 560.5 | K31: 408.5 | L31: 34.064282 | M31: 268.74116 | N31: 343.42481 | O31: =IFERROR(_xlfn.XLOOKUP(A31,$T$1:$T$13,$S$1:$S$13,,0),0) -> 0 | P31: =IFERROR(_xlfn.XLOOKUP(A31,$T$1:$T$13,$U$1:$U$13,,0),0) -> 0 | Q31: =IF(P31>1,P31,G31) -> 5280 | R31: =IFERROR(_xlfn.XLOOKUP(A31,$T$1:$T$13,$V$1:$V$13,,0),0) -> 0
A32: 182 E Kelsey Ave, Salt Lake City, UT 84111 | B32: Salt Lake City | C32: Salt Lake City | D32: https://www.zillow.com/homedetails/182-E-Kelsey-Ave-Salt-Lake-City-UT-84111/12757584_zpid/ | E32: 849900 | F32: 2806 | G32: 4620 | H32: 7 | I32: 212475 | J32: 417.8675 | K32: 304.5475 | L32: 86.065787 | M32: 271.18698 | N32: 252.62191 | O32: =IFERROR(_xlfn.XLOOKUP(A32,$T$1:$T$13,$S$1:$S$13,,0),0) -> 0 | P32: =IFERROR(_xlfn.XLOOKUP(A32,$T$1:$T$13,$U$1:$U$13,,0),0) -> 0 | Q32: =IF(P32>1,P32,G32) -> 4620 | R32: =IFERROR(_xlfn.XLOOKUP(A32,$T$1:$T$13,$V$1:$V$13,,0),0) -> 0
A33: 64 F St, Salt Lake City, UT 84103 | B33: Avenues | C33: Salt Lake City | D33: https://www.zillow.com/homedetails/64-F-St-Salt-Lake-City-UT-84103/2111734021_zpid/ | E33: 979000 | F33: 1942 | G33: 0 | I33: 244750 | J33: 481.34167 | K33: 350.80833 | L33: 66.086343 | M33: 271.94444 | N33: 1067.8931 | O33: =IFERROR(_xlfn.XLOOKUP(A33,$T$1:$T$13,$S$1:$S$13,,0),0) -> 0 | P33: =IFERROR(_xlfn.XLOOKUP(A33,$T$1:$T$13,$U$1:$U$13,,0),0) -> 0 | Q33: =IF(P33>1,P33,G33) -> 0 | R33: =IFERROR(_xlfn.XLOOKUP(A33,$T$1:$T$13,$V$1:$V$13,,0),0) -> 0
A34: 1309 Hidden Creek Ct, Salt Lake City, UT 84117 | B34: Millcreek | C34: Salt Lake City | D34: https://www.zillow.com/homedetails/1309-Hidden-Creek-Ct-Salt-Lake-City-UT-84117/12858462_zpid/ | E34: 950000 | F34: 2785 | G34: 2640 | H34: 4 | I34: 237500 | J34: 467.08333 | K34: 340.41667 | L34: 143.06534 | M34: 277.53433 | N34: 368.47322 | O34: =IFERROR(_xlfn.XLOOKUP(A34,$T$1:$T$13,$S$1:$S$13,,0),0) -> 0 | P34: =IFERROR(_xlfn.XLOOKUP(A34,$T$1:$T$13,$U$1:$U$13,,0),0) -> 5890 | Q34: =IF(P34>1,P34,G34) -> 5890 | R34: =IFERROR(_xlfn.XLOOKUP(A34,$T$1:$T$13,$V$1:$V$13,,0),0) -> CapRate: 5.6%; GRM: 156.5
A35: 1815 E Hillcrest Ave, Salt Lake City, UT 84106 | B35: Salt Lake City | C35: Salt Lake City | D35: https://www.zillow.com/homedetails/1815-E-Hillcrest-Ave-Salt-Lake-City-UT-84106/12777839_zpid/ | E35: 685000 | F35: 2084 | G35: 2640 | H35: 4 | I35: 171250 | J35: 336.79167 | K35: 245.45833 | L35: 9.8127199 | M35: 277.77778 | N35: 307.05574 | O35: =IFERROR(_xlfn.XLOOKUP(A35,$T$1:$T$13,$S$1:$S$13,,0),0) -> 0 | P35: =IFERROR(_xlfn.XLOOKUP(A35,$T$1:$T$13,$U$1:$U$13,,0),0) -> 0 | Q35: =IF(P35>1,P35,G35) -> 2640 | R35: =IFERROR(_xlfn.XLOOKUP(A35,$T$1:$T$13,$V$1:$V$13,,0),0) -> 0
A36: 2200 S Wasatch Dr, Salt Lake City, UT 84109 | B36: Salt Lake City | C36: Salt Lake City | D36: https://www.zillow.com/homedetails/2200-S-Wasatch-Dr-Salt-Lake-City-UT-84109/12779572_zpid/ | E36: 850000 | F36: 2717 | G36: 2640 | H36: 4 | I36: 212500 | J36: 417.91667 | K36: 304.58333 | L36: 163.06446 | M36: 281.64347 | N36: 333.50586 | O36: =IFERROR(_xlfn.XLOOKUP(A36,$T$1:$T$13,$S$1:$S$13,,0),0) -> 0 | P36: =IFERROR(_xlfn.XLOOKUP(A36,$T$1:$T$13,$U$1:$U$13,,0),0) -> 0 | Q36: =IF(P36>1,P36,G36) -> 2640 | R36: =IFERROR(_xlfn.XLOOKUP(A36,$T$1:$T$13,$V$1:$V$13,,0),0) -> 0
A37: 1145 E Kensington Ave, Salt Lake City, UT 84105 | B37: Salt Lake City | C37: Salt Lake City | D37: https://www.zillow.com/homedetails/1145-E-Kensington-Ave-Salt-Lake-City-UT-84105/12769747_zpid/ | E37: 734999 | F37: 1804 | G37: 2640 | H37: 4 | I37: 183749.75 | J37: 361.37451 | K37: 263.37464 | L37: 134.06436 | M37: 283.01848 | N37: 356.83848 | O37: =IFERROR(_xlfn.XLOOKUP(A37,$T$1:$T$13,$S$1:$S$13,,0),0) -> 0 | P37: =IFERROR(_xlfn.XLOOKUP(A37,$T$1:$T$13,$U$1:$U$13,,0),0) -> 0 | Q37: =IF(P37>1,P37,G37) -> 2640 | R37: =IFERROR(_xlfn.XLOOKUP(A37,$T$1:$T$13,$V$1:$V$13,,0),0) -> 0
A38: 1978 S Windsor St, Salt Lake City, UT 84105 | B38: Salt Lake City | C38: Salt Lake City | D38: https://www.zillow.com/homedetails/1978-S-Windsor-St-Salt-Lake-City-UT-84105/12770679_zpid/ | E38: 1149000 | F38: 3017 | G38: 3960 | H38: 6 | I38: 287250 | J38: 564.925 | K38: 411.725 | L38: 187.0645 | M38: 283.56367 | N38: 350.00428 | O38: =IFERROR(_xlfn.XLOOKUP(A38,$T$1:$T$13,$S$1:$S$13,,0),0) -> 0 | P38: =IFERROR(_xlfn.XLOOKUP(A38,$T$1:$T$13,$U$1:$U$13,,0),0) -> 0 | Q38: =IF(P38>1,P38,G38) -> 3960 | R38: =IFERROR(_xlfn.XLOOKUP(A38,$T$1:$T$13,$V$1:$V$13,,0),0) -> 0
A39: 365 S Elizabeth St, Salt Lake City, UT 84102 | B39: Salt Lake City | C39: Salt Lake City | D39: https://www.zillow.com/homedetails/365-S-Elizabeth-St-Salt-Lake-City-UT-84102/141868419_zpid/ | E39: 879000 | F39: 3100 | G39: 3960 | H39: 6 | I39: 219750 | J39: 432.175 | K39: 314.975 | L39: 106.85865 | M39: 286.13281 | N39: 263.85753 | O39: =IFERROR(_xlfn.XLOOKUP(A39,$T$1:$T$13,$S$1:$S$13,,0),0) -> 0 | P39: =IFERROR(_xlfn.XLOOKUP(A39,$T$1:$T$13,$U$1:$U$13,,0),0) -> 0 | Q39: =IF(P39>1,P39,G39) -> 3960 | R39: =IFERROR(_xlfn.XLOOKUP(A39,$T$1:$T$13,$V$1:$V$13,,0),0) -> 0
A40: 609 E 6th Ave, Salt Lake City, UT 84103 | B40: Avenues | C40: Salt Lake City | D40: https://www.zillow.com/homedetails/609-E-6th-Ave-Salt-Lake-City-UT-84103/305056306_zpid/ | E40: 1000000 | F40: 1758 | G40: 2640 | H40: 4 | I40: 250000 | J40: 491.66667 | K40: 358.33333 | L40: 11.063391 | M40: 288.35063 | N40: 492.74744 | O40: =IFERROR(_xlfn.XLOOKUP(A40,$T$1:$T$13,$S$1:$S$13,,0),0) -> 0 | P40: =IFERROR(_xlfn.XLOOKUP(A40,$T$1:$T$13,$U$1:$U$13,,0),0) -> 0 | Q40: =IF(P40>1,P40,G40) -> 2640 | R40: =IFERROR(_xlfn.XLOOKUP(A40,$T$1:$T$13,$V$1:$V$13,,0),0) -> 0
A41: 465 E 3300 S, Salt Lake City, UT 84115 | B41: Salt Lake City | C41: Salt Lake City | D41: https://www.zillow.com/homedetails/465-E-3300-S-Salt-Lake-City-UT-84115/83825002_zpid/ | E41: 1200000 | F41: 2270 | G41: 1980 | H41: 3 | I41: 300000 | J41: 590 | K41: 430 | L41: 124.06523 | M41: 291.61604 | N41: 597.65051 | O41: =IFERROR(_xlfn.XLOOKUP(A41,$T$1:$T$13,$S$1:$S$13,,0),0) -> 0 | P41: =IFERROR(_xlfn.XLOOKUP(A41,$T$1:$T$13,$U$1:$U$13,,0),0) -> 0 | Q41: =IF(P41>1,P41,G41) -> 1980 | R41: =IFERROR(_xlfn.XLOOKUP(A41,$T$1:$T$13,$V$1:$V$13,,0),0) -> 0
...

Sheet DATA>>

Sheet Inputs
A1: ASSUMPTIONS
L2: SLC Duplex
A3: MLS # | K3: Springville Duplex | L3: 1692304
B4: 1309 Hidden Ct | C4: =B5/4 -> #N/A | E4: 1309 Hidden Ct | F4: UofU 7-plex | G4: Sugarhouse triplex | H4: 1600 S 4 plex | I4: Texas 1 | J4: Texas 2 | M4: Millcreek fourplex | N4: UofU 4-plex | O4: Marmalade Duplex
A5: Monthly Rent Yr1 | B5: =_xlfn.XLOOKUP(1,Pivot!$O$10:$O$131,Pivot!$Q$10:$Q$131,,0) -> #N/A | C5: =XLOOKUP(1,Pivot!$O$10:$O$131,Pivot!$Q$10:$Q$131,,0) | E5: =_xlfn.XLOOKUP(1,Pivot!$O$10:$O$131,Pivot!$Q$10:$Q$131,,0) -> #N/A | F5: =1795+995+1195+1195+1495+1150 -> 7825 | G5: =2600+1400+1350 -> 5350 | H5: =1350+1200*3 -> 4950 | I5: =4*700 -> 2800 | J5: =700*4 -> 2800 | K5: =750+1250 -> 2000 | L5: =2500 -> 2500 | M5: =1925+1100+1800+1800 -> 6625 | N5: =1875+1200+1150+1500 -> 5725 | O5: 4900
A6: Annual Rent in Year 1 | B6: =B5*12 -> #N/A | E6: =E5*12 -> #N/A | F6: =F5*12 -> 93900 | G6: =G5*12 -> 64200 | H6: =H5*12 -> 59400 | I6: =I5*12 -> 33600 | J6: =J5*12 -> 33600 | K6: =K5*12 -> 24000 | L6: =L5*12 -> 30000 | ... O6: =O5*12 -> 58800
A7: Change in Rent | B7: 0.03 | E7: 0.03 | F7: 0.035 | G7: 0.035 | H7: 0.035 | I7: =I23 -> 0.025 | J7: =J23 -> 0.025 | K7: =K23 -> 0.025 | L7: =L23 -> 0.025 | M7: =M23 -> 0.025 | N7: =N23 -> 0.025 | O7: =O23 -> 0.025
A8: Vacancy & Bad Debts Losses | B8: 0.01 | E8: 0.01 | F8: 0.01 | G8: 0.01 | H8: 0.01 | I8: 0.03 | J8: 0.03 | K8: 0.03 | L8: 0.03 | M8: 0.03 | N8: 0.03 | O8: 0.03
A9: Operating Expenses in Year 1 | B9: =B42 -> #N/A | E9: =E42 -> #N/A | F9: =F42 -> 23845.549 | G9: =G42 -> 13558.744 | H9: =H42 -> 13513.289 | I9: =I42 -> 8743.7081 | J9: =J42 -> 9309.7608 | K9: =K42 -> 6577.3374 | L9: =L42 -> 11260.946 | ... O9: =O42 -> 12745.634
A10: Growth Rate in Operating Expenses | B10: =B23 -> 0.025 | C10: % per Year | E10: =E23 -> 0.025 | F10: =F23 -> 0.025 | G10: =G23 -> 0.025 | H10: =H23 -> 0.025 | I10: =I23 -> 0.025 | J10: =J23 -> 0.025 | K10: =K23 -> 0.025 | L10: =L23 -> 0.025 | ... O10: =O23 -> 0.025
A11: Purchase Price | B11: =_xlfn.XLOOKUP(1,Pivot!$O$10:$O$131,Pivot!$E$10:$E$131,,0)*(1-Pivot!$Q$2) -> #N/A | C11: =_xlfn.XLOOKUP(1,Pivot!$O$10:$O$131,Pivot!$E$10:$E$131,,0)*(1-Pivot!$Q$3-Pivot!$Q$2) -> #N/A | E11: =_xlfn.XLOOKUP(1,Pivot!$O$10:$O$131,Pivot!$E$10:$E$131,,0)*(1-Pivot!$Q$3-Pivot!$Q$2) -> #N/A | F11: =1899000*0.97 -> 1842030 | G11: 970000 | H11: =1000000*0.97 -> 970000 | I11: 330000 | J11: 420000 | K11: 310000 | L11: =(460000-10000)*101.75% -> 457875 | M11: 1195000 | N11: 1195000 | O11: 825000
A12: Loan-to-Value Ratio | B12: =1-B13/B11 -> #N/A | C12: % of Asking Price | E12: =1-E13/E11 -> #N/A | F12: 0.75 | G12: 0.75 | H12: 0.75 | I12: =(1-I13/I11) -> 0.95 | J12: =(1-J13/J11) -> 0.95 | K12: =(1-K13/K11) -> 0.9 | L12: =(1-L13/L11) -> 0.95 | M12: 0.8 | N12: 0.8 | O12: 0.8
A13: Down Payment | B13: =MIN(Pivot!H1,B11*0.25) -> #N/A | E13: =MIN(Pivot!K1,E11*0.25) -> #N/A | F13: =F11*(1-F12) -> 460507.5 | G13: =G11*(1-G12) -> 242500 | H13: =H11*(1-H12) -> 242500 | I13: =I11*0.05 -> 16500 | J13: =J11*0.05 -> 21000 | K13: =K11*0.1 -> 31000 | L13: =L11*0.05 -> 22893.75 | M13: =M11*(1-M12) -> 239000 | N13: =N11*(1-N12) -> 239000 | O13: =O11*(1-O12) -> 165000
A14: Mortgage Interest Rate | B14: 0.067 | C14: % Annual | E14: 0.067 | F14: 0.068 | G14: 0.07 | H14: 0.07 | I14: 0.03 | J14: 0.03 | K14: 0.025 | L14: 0.025 | M14: 0.06 | N14: 0.06 | O14: 0.06
A15: Mortgage Amortization Period | B15: 360 | C15: Months - Monthly Compounding | E15: 360 | F15: 360 | G15: 360 | H15: 360 | I15: 360 | J15: 360 | K15: 360 | L15: 360 | M15: 360 | N15: 360 | O15: 360
A16: Land-to-Value Ratio | B16: 0.5 | C16: % Non-depreciable for Tax | E16: 0.5 | F16: 0.5 | G16: 0.5 | H16: 0.5 | I16: 0.5 | J16: 0.5 | K16: 0.5 | L16: 0.5 | M16: 0.5 | N16: 0.5 | O16: 0.5
A17: Useful Life | B17: 27.5 | C17: Years of Tax Depreciable Life | E17: 27.5 | F17: 27.5 | G17: 27.5 | H17: 27.5 | I17: 27.5 | J17: 27.5 | K17: 27.5 | L17: 27.5 | M17: 27.5 | N17: 27.5 | O17: 27.5
A18: Ordinary Income Tax Rate | B18: 0.25 | C18: % Marginal Tax Rate | E18: 0.25 | F18: 0.25 | G18: 0.25 | H18: 0.25 | I18: 0.25 | J18: 0.25 | K18: 0.25 | L18: 0.25 | M18: 0.25 | N18: 0.25 | O18: 0.25
A19: Required Rate of Return--100% Equity | B19: 0.1 | C19: % per Year | E19: 0.1 | F19: 0.1 | G19: 0.1 | H19: 0.1 | I19: 0.1 | J19: 0.1 | K19: 0.1 | L19: 0.1 | M19: 0.1 | N19: 0.1 | O19: 0.1
A20: Required Equity for PMI To Drop Off | B20: 0.22 | C20: % | E20: 0.22 | F20: 0.22 | G20: 0.22 | H20: 0.22 | I20: 0.22 | J20: 0.22 | K20: 0.22 | L20: 0.22 | M20: 0.22 | N20: 0.22 | O20: 0.22
A22: Appreciation Rate | B22: 0.025 | C22: % per Year | E22: 0.025 | F22: 0.035 | G22: 0.035 | H22: 0.035 | I22: 0.01 | J22: 0.025 | K22: 0.025 | L22: 0.025 | M22: 0.025 | N22: 0.025 | O22: 0.025
A23: Inflation | B23: 0.025 | C23: % per Year | E23: 0.025 | F23: 0.025 | G23: 0.025 | H23: 0.025 | I23: 0.025 | J23: 0.025 | K23: 0.025 | L23: 0.025 | M23: 0.025 | N23: 0.025 | O23: 0.025
A24: Monthly Mortgage Payment | B24: =PMT(B14/12,B15,B11-B13) -> #N/A | C24: =B24*12 -> #N/A | E24: =PMT(E14/12,E15,E11-E13) -> #N/A | F24: =PMT(F14/12,F15,F11-F13) -> -9006.4932 | G24: =PMT(G14/12,G15,G11-G13) -> -4840.0757 | H24: =PMT(H14/12,H15,H11-H13) -> -4840.0757 | I24: =PMT(I14/12,I15,I11-I13) -> -1321.7286 | J24: =PMT(J14/12,J15,J11-J13) -> -1682.2001 | K24: =PMT(K14/12,K15,K11-K13) -> -1102.3873 | L24: =PMT(L14/12,L15,L11-L13) -> -1718.7018 | ... O24: =PMT(O14/12,O15,O11-O13) -> -3957.0335
A25: NPV Discount Rate | B25: N/A | C25: % per Year | E25: N/A | F25: N/A | G25: N/A | H25: N/A | I25: N/A | J25: N/A | K25: N/A | L25: N/A | M25: N/A | N25: N/A | O25: N/A
A27: Secondary Loan Amount | B27: 0 | E27: 0 | F27: 0 | G27: 0 | H27: 0 | I27: 0 | J27: 0 | K27: 0 | L27: 0 | M27: 0 | N27: 0 | O27: 0
A28: Secondary Loan Rate | B28: 0.08 | E28: 0.08 | F28: 0.08 | G28: 0.08 | H28: 0.08 | I28: 0.06625 | J28: 0.06625 | K28: 0.06625 | L28: 0.06625 | M28: 0.06625 | N28: 0.06625 | O28: 0.06625
A30: OPERATING EXPENSES
A32: Management Expense | B32: 0.01 | E32: 0.01 | F32: 0.01 | G32: 0.01 | H32: 0.01 | I32: 0 | J32: 0 | K32: 0 | L32: 0 | M32: 0 | N32: 0 | O32: 0
A33: Management Fees | B33: =7*300/2 -> 1050 | E33: =7*300/2 -> 1050 | F33: =7*300/2 -> 1050 | G33: =G5/660/2*300/2 -> 607.95455 | H33: =H5/660/2*300/2 -> 562.5 | I33: =I5/660/2*300/2 -> 318.18182 | J33: =J5/660/2*300/2 -> 318.18182 | K33: =K5/660/2*300/2 -> 227.27273 | L33: =L5/660/2*300/2 -> 284.09091 | M33: =M5/660/2*300/2 -> 752.84091 | N33: =N5/660/2*300/2 -> 650.56818 | O33: =O5/660/2*300/2 -> 556.81818
A34: Advertising/Agent Fees | B34: 0 | E34: 0 | F34: 0 | G34: 0 | H34: 0 | I34: 0 | J34: 0 | K34: 0 | L34: 0 | M34: 0 | N34: 0 | O34: 0
A35: PMI | B35: 0 | E35: 0 | F35: 0 | G35: 0 | H35: 0 | I35: =350*12 -> 4200 | J35: =350*12 -> 4200 | K35: =205/305*K11/1000*12 -> 2500.3279 | L35: =IF(L13/L11<0.05,0.0085,0.008)*L11 -> 3663 | M35: 0 | N35: 0 | O35: 0
A36: Maintenance / Misc | B36: =B11*0.005 -> #N/A | E36: =E11*0.005 -> #N/A | F36: =F11*0.005 -> 9210.15 | G36: =G11*0.005 -> 4850 | H36: =H11*0.005 -> 4850 | I36: =I11*0.005 -> 1650 | J36: =I36 -> 1650 | K36: 1000 | L36: =L11*0.0075 -> 3434.0625 | M36: 3000 | N36: 3000 | O36: 3000
A37: Utilities / HOA | B37: =1300/775000*B11+4200 -> #N/A | E37: =1300/775000*E11+4200 -> #N/A | F37: 2000 | G37: 2000 | H37: 2000 | I37: 500 | J37: 500 | K37: 900 | L37: 1000 | M37: 4000 | N37: 4000 | O37: 4000
A38: Hazard Insurance | B38: =_xlfn.XLOOKUP(1,Pivot!$O$10:$O$131,Pivot!$K$10:$K$131,,0)*12 -> #N/A | C38: =600*12 -> 7200 | E38: 3000 | F38: =0.45%*F11 -> 8289.135 | G38: =0.45%*G11 -> 4365 | H38: =0.45%*H11 -> 4365 | I38: =0.45%*I11 -> 1485 | J38: =0.45%*J11 -> 1890 | K38: =0.45%*K11 -> 1395 | L38: =0.45%*L11 -> 2060.4375 | M38: =0.45%*M11 -> 5377.5 | ... O38: =0.45%*O11 -> 3712.5
A39: Property Taxes | B39: =_xlfn.XLOOKUP(1,Pivot!$O$10:$O$131,Pivot!$J$10:$J$131,,0)*12 -> #N/A | C39: =_xlfn.XLOOKUP(1,Pivot!$O$10:$O$131,Pivot!$J$10:$J$131,,0)*12 -> #N/A | E39: 5534 | F39: =1700/950000*F11 -> 3296.2642 | G39: =1700/950000*G11 -> 1735.7895 | H39: =1700/950000*H11 -> 1735.7895 | I39: =1700/950000*I11 -> 590.52632 | J39: =1700/950000*J11 -> 751.57895 | K39: =1700/950000*K11 -> 554.73684 | L39: =1700/950000*L11 -> 819.35526 | M39: =1700/950000*M11 -> 2138.4211 | ... O39: =1700/950000*O11 -> 1476.3158
A40: Interest Expense (Secondary Loan) | B40: =B28*B27 -> 0 | E40: =E28*E27 -> 0 | F40: =F28*F27 -> 0 | G40: =G28*G27 -> 0 | H40: =H28*H27 -> 0 | I40: =I28*I27 -> 0 | J40: =J28*J27 -> 0 | K40: =K28*K27 -> 0 | L40: =L28*L27 -> 0 | ... O40: =O28*O27 -> 0
C41: =B39/12 -> #N/A
A42: TOTAL | B42: =SUM(B33:B40) -> #N/A | E42: =SUM(E33:E40) -> #N/A | F42: =SUM(F33:F40) -> 23845.549 | G42: =SUM(G33:G40) -> 13558.744 | H42: =SUM(H33:H40) -> 13513.289 | I42: =SUM(I33:I40) -> 8743.7081 | J42: =SUM(J33:J40) -> 9309.7608 | K42: =SUM(K33:K40) -> 6577.3374 | L42: =SUM(L33:L40) -> 11260.946 | ... O42: =SUM(O33:O40) -> 12745.634
A44: CALCULATIONS
A46: Monthly Depreciation | B46: =(B11*(1-B16))/(B17*12) -> #N/A | E46: =(E11*(1-E16))/(E17*12) -> #N/A | F46: =(F11*(1-F16))/(F17*12) -> 2790.9545 | G46: =(G11*(1-G16))/(G17*12) -> 1469.697 | H46: =(H11*(1-H16))/(H17*12) -> 1469.697 | I46: =(I11*(1-I16))/(I17*12) -> 500 | J46: =(J11*(1-J16))/(J17*12) -> 636.36364 | K46: =(K11*(1-K16))/(K17*12) -> 469.69697 | L46: =(L11*(1-L16))/(L17*12) -> 693.75 | ... O46: =(O11*(1-O16))/(O17*12) -> 1250
...

Sheet Financials
